Workbook

Sheet C
A1: CODICE | B1: DESCRIZIONE | C1: QUANTITà | D1: LOTTO | E1: FAMIGLIA
A2: 2283 | B2: PIZZICOTTA CLASSICA RETTANGOLARE 20x30 | C2: 856 | D2: 200126 | E2: PIZZA ATM
A3: 2283 | B3: PIZZICOTTA CLASSICA RETTANGOLARE 20x30 | C3: 832 | D3: 130126 | E3: PIZZA ATM
A4: 2285 | B4: PIZZICOTTA NOIR RETTANGOLARE 20X30 | C4: 608 | D4: 200126 | E4: PIZZA ATM
A5: 2543 | B5: PIZZICOTTA PINSA ROMANA 240 G | C5: 656 | D5: 200126 | E5: PIZZA ATM
A6: 2553 | B6: PIZZICOTTA FOCACCINE CLASSICHE 75G | C6: 960 | D6: 210126 | E6: PIZZA ATM
A7: 2735 | B7: CLASSICA RETT MONO (10PZ) CONG. | C7: 3700 | D7: 270126 | E7: PIZZA GELO
A8: 2738 | B8: BASE PIZZA TONDA CLASSICA (15PZ) CONG | C8: 8730 | D8: 280126 | E8: PIZZA GELO
A9: 2738 | B9: BASE PIZZA TONDA CLASSICA (15PZ) CONG | C9: 675 | D9: 270126 | E9: PIZZA GELO | I9: {=_xlfn._xlws.PY(0,1,A1:E1000)} -> #VALUE! | J9: {=_FV(I9,"arrayPreview")} -> #VALUE! | K9: {=_xlfn._DF_Python_str(I9)} -> #VALUE!
A10: 2738 | B10: BASE PIZZA TONDA CLASSICA (15PZ) CONG | C10: 2835 | D10: 260126 | E10: PIZZA GELO
A11: 2738 | B11: BASE PIZZA TONDA CLASSICA (15PZ) CONG | C11: 2130 | D11: 230126 | E11: PIZZA GELO | I11: {=_xlfn._xlws.PY(1,1,A1:E1000)} -> #VALUE!
A12: 2738 | B12: BASE PIZZA TONDA CLASSICA (15PZ) CONG | C12: 1950 | D12: 220126 | E12: PIZZA GELO
A13: 2738 | B13: BASE PIZZA TONDA CLASSICA (15PZ) CONG | C13: 1215 | D13: 210126 | E13: PIZZA GELO | I13: {=_xlfn._xlws.PY(2,1,A1:E1000)} -> #VALUE!
A14: 2738 | B14: BASE PIZZA TONDA CLASSICA (15PZ) CONG | C14: 720 | D14: 190126 | E14: PIZZA GELO | I14: QUALE E' LA COPPIA Più PRODUTTIVA? (CASO IN CONSIDERAZIONE: SOLO 2 REFERENZE PER GIORNATA)
A15: 2738 | B15: BASE PIZZA TONDA CLASSICA (15PZ) CONG | C15: 1290 | D15: 160126 | E15: PIZZA GELO | I15: {=_xlfn._xlws.PY(3,1,A1:E1000)} -> #VALUE! | J15: {=_FV(I15,"arrayPreview")} -> #VALUE!
A16: 2738 | B16: BASE PIZZA TONDA CLASSICA (15PZ) CONG | C16: 720 | D16: 120126 | E16: PIZZA GELO
A17: 4808 | B17: PIZZICOTTA CLASSICA RETTAN.20X30 AMBIENT | C17: 312 | D17: 210126 | E17: PIZZA AMBIENT
A18: 4808 | B18: PIZZICOTTA CLASSICA RETTAN.20X30 AMBIENT | C18: 248 | D18: 210126 | E18: PIZZA AMBIENT
A19: 4855 | B19: PIZZICOTTA PINSA ROMANA 240g AMBIENT | C19: 5080 | D19: 270126 | E19: PIZZA AMBIENT
A20: 9000 | B20: MALFATTO 27PZ GELO | C20: 4320 | D20: 190126 | E20: PANE
A21: 9000 | B21: MALFATTO 27PZ GELO | C21: 6480 | D21: 160126 | E21: PANE
A22: 9001 | B22: MALFATTO 36PZ GELO | C22: 6084 | D22: 250126 | E22: PANE
A23: 9001 | B23: MALFATTO 36PZ GELO | C23: 5184 | D23: 230126 | E23: PANE
A24: 9001 | B24: MALFATTO 36PZ GELO | C24: 4896 | D24: 220126 | E24: PANE
A25: 9001 | B25: MALFATTO 36PZ GELO | C25: 4608 | D25: 200126 | E25: PANE
A26: 9001 | B26: MALFATTO 36PZ GELO | C26: 2052 | D26: 190126 | E26: PANE
A27: 9001 | B27: MALFATTO 36PZ GELO | C27: 1548 | D27: 160126 | E27: PANE
A28: 9001 | B28: MALFATTO 36PZ GELO | C28: 3780 | D28: 150126 | E28: PANE
A29: 9001 | B29: MALFATTO 36PZ GELO | C29: 2304 | D29: 130126 | E29: PANE | I29: {=_xlfn._xlws.PY(4,1)} -> #VALUE! | J29: {=_FV(I29,"arrayPreview")} -> #VALUE!
A30: 9003 | B30: PANNOCCHIA 36PZ GELO | C30: 2376 | D30: 250126 | E30: PANE
A31: 9003 | B31: PANNOCCHIA 36PZ GELO | C31: 2304 | D31: 230126 | E31: PANE
A32: 9003 | B32: PANNOCCHIA 36PZ GELO | C32: 4284 | D32: 200126 | E32: PANE
A33: 9003 | B33: PANNOCCHIA 36PZ GELO | C33: 4896 | D33: 190126 | E33: PANE
A34: 9003 | B34: PANNOCCHIA 36PZ GELO | C34: 1620 | D34: 160126 | E34: PANE
A35: 9003 | B35: PANNOCCHIA 36PZ GELO | C35: 2304 | D35: 150126 | E35: PANE
A36: 9003 | B36: PANNOCCHIA 36PZ GELO | C36: 2304 | D36: 130126 | E36: PANE | N36: in che lotto è presente la coppia più produttiva? (SOLO 2 CODICI)
A37: 9004 | B37: TRECCIA 36PZ GELO | C37: 1620 | D37: 160126 | E37: PANE | N37: {=_xlfn._xlws.PY(5,1,A1:E1000)} -> #VALUE! | O37: {=_FV(N37,"arrayPreview")} -> #VALUE!
A38: 9005 | B38: PANE CURCUMA E PEPE 36PZ GELO | C38: 936 | D38: 150126 | E38: PANE
A39: 9013 | B39: PANE RIGATO 36PZ GELO | C39: 2592 | D39: 250126 | E39: PANE
A40: 9013 | B40: PANE RIGATO 36PZ GELO | C40: 1728 | D40: 150126 | E40: PANE | N40: in quali lotti sono state calcolate le medie?
...

Sheet B
A1: CODICE | B1: DESCRIZIONE | C1: QUANTITà | D1: LOTTO | E1: FAMIGLIA
A2: 2283 | B2: PIZZICOTTA CLASSICA RETTANGOLARE MONO | C2: 728 | D2: 300125 | E2: PIZZA ATM
A3: 2283 | B3: PIZZICOTTA CLASSICA RETTANGOLARE MONO | C3: 1528 | D3: 290125 | E3: PIZZA ATM
A4: 2283 | B4: PIZZICOTTA CLASSICA RETTANGOLARE MONO | C4: 736 | D4: 240125 | E4: PIZZA ATM
A5: 2283 | B5: PIZZICOTTA CLASSICA RETTANGOLARE MONO | C5: 1520 | D5: 170125 | E5: PIZZA ATM
A6: 2285 | B6: PIZZICOTTA TONDA NOIR MINI | C6: 712 | D6: 160125 | E6: PIZZA ATM
A7: 2289 | B7: PIZZICOTTA CLASSICA TONDA | C7: 552 | D7: 300125 | E7: PIZZA ATM
A8: 2289 | B8: PIZZICOTTA CLASSICA TONDA | C8: 1104 | D8: 290125 | E8: PIZZA ATM
A9: 2289 | B9: PIZZICOTTA CLASSICA TONDA | C9: 416 | D9: 160125 | E9: PIZZA ATM
A10: 2290 | B10: PIZZICOTTA INTEGRALE RETTANG. MINI | C10: 360 | D10: 300125 | E10: PIZZA ATM
A11: 2543 | B11: PIZZICOTTA PINSA ROMANA OVALE ATM 240 G | C11: 680 | D11: 240125 | E11: PIZZA ATM
A12: 2553 | B12: PIZZICOTTA FOCACCINE CLASSICHE | C12: 780 | D12: 310125 | E12: PIZZA ATM
A13: 2553 | B13: PIZZICOTTA FOCACCINE CLASSICHE | C13: 840 | D13: 240125 | E13: PIZZA ATM
... A1504: 9284 | B1504: PIZZICOTTA RETTANGOLARE 28X50 | C1504: 504 | D1504: 181225 | E1504: PIZZA GELO
E1505: .
E1506: .
E1507: .
E1508: .
E1509: .
E1510: .
E1511: .
E1512: .
E1513: .
E1514: .
E1515: .
E1516: .
... E3662: .

Sheet A
A1: REFERENZA | B1: DESCRIZIONE | C1: DATA PRODUZIONE | D1: LOTTO | E1: TIPOLOGIA | F1: TURNO | G1: ORE TOT FASE | L1: IN BASE AI DATI DI PRODUTTIVITA' E ALLE ORE CARICATE PROPONIMI UN N. PZ PER LOTTO CON 11 PAX 8 ORE
A2: 9188 | B2: Base 20*40 400 g gelo pretagliata | C2: 13/01/2025 | D2: 130125 | E2: PIZZA GELO | F2: 1 | G2: 72 | L2: {=_xlfn._xlws.PY(7,1,A!A1:G10000,B!A1:E10000)} -> #VALUE! | M2: {=_FV(L2,"arrayPreview")} -> #VALUE!
A3: 9053 | B3: BASE PIZZA LINGUA ROMANA 55X19 GELO | C3: 14/01/2025 | D3: 140125 | E3: PIZZA GELO LB | F3: 1 | G3: 47 | Z3: primi_5 = risultato.head(5) ultimi_5 = risultato.tail(5) # tutto quello che sta in mezzo mezzo = risultato.iloc[5:-5] output = { "PRIMI 5": primi_5, "MEZZO": mezzo, "ULTIMI 5": ultimi_5 } output
A4: 2738 | B4: BASE PIZZA TONDA (15PZ) CONG | C4: 14/01/2025 | D4: 140125 | E4: PIZZA GELO | F4: 1 | G4: 24
A5: 9053 | B5: BASE PIZZA LINGUA ROMANA 55X19 GELO | C5: 15/01/2025 | D5: 150125 | E5: PIZZA GELO LB | F5: 1 | G5: 63
A6: 2289 | B6: BASE PIZZA TONDA CLASSICA | C6: 16/01/2025 | D6: 160125 | E6: PIZZA ATM | F6: 1 | G6: 9
A7: 2738 | B7: BASE PIZZA TONDA (15PZ) CONG | C7: 16/01/2025 | D7: 160125 | E7: PIZZA GELO | F7: 1 | G7: 19.5
A8: 9201 | B8: PIZZICOTTA PINSA ROMANA 240 G | C8: 16/01/2025 | D8: 160125 | E8: PIZZA GELO | F8: 1 | G8: 15 | M8: IN BASE AI DATI DI PRODUTTIVITA' E ALLE ORE CARICATE PROPONIMI UN N. PZ PER LOTTO CON
A9: 2285 | B9: BASE PIZZA NOIR MINI D.28 (8PZ) | C9: 16/01/2025 | D9: 160125 | E9: PIZZA ATM | F9: 1 | G9: 19.5 | K9: COD. PROD | L9: 2738 | M9: DATO UN CODICE DIMMI IL LOTTO CCST EFFETTIVO PER L'ANNO 2025
A10: 2283 | B10: BASE PALASTYLE (8PZ) | C10: 17/01/2025 | D10: 170125 | E10: PIZZA ATM | F10: 1 | G10: 42 | K10: ORE STD | L10: =INDEX(Foglio2!D:D,MATCH(A!L9,Foglio2!A:A,0)) -> 104
A11: 9188 | B11: Base 20*40 400 g gelo pretagliata | C11: 17/01/2025 | D11: 170125 | E11: PIZZA GELO | F11: 1 | G11: 36 | K11: PZ STD | L11: =INDEX(Foglio2!B:B,MATCH(L9,Foglio2!A:A,0)) -> 4320 | M11: {=_xlfn._xlws.PY(8,1,L9,L10,L11,L12,L13,L14,A!A1:G10000,B!A1:E10000)} -> #VALUE! | N11: {=_FV(M11,"arrayPreview")} -> #VALUE!
A12: 9227 | B12: BASE PIZZA DOUGHBOYS (12PZ) CONG | C12: 20/01/2025 | D12: 200125 | E12: PIZZA GELO | F12: 1 | G12: 74 | K12: CIV CCST | L12: =INDEX(Foglio2!E:E,MATCH(L9,Foglio2!A:A,0)) -> 3532.65
A13: 9227 | B13: BASE PIZZA DOUGHBOYS (12PZ) CONG | C13: 21/01/2025 | D13: 210125 | E13: PIZZA GELO | F13: 1 | G13: 42 | K13: COST FISS | L13: 0
A14: 9188 | B14: Base 20*40 400 g gelo pretagliata | C14: 21/01/2025 | D14: 210125 | E14: PIZZA GELO | F14: 1 | G14: 21 | K14: MARGINE | L14: 35
A15: 9227 | B15: BASE PIZZA DOUGHBOYS (12PZ) CONG | C15: 22/01/2025 | D15: 220125 | E15: PIZZA GELO | F15: 1 | G15: 110 | M15: {=_xlfn._xlws.PY(9,1,L9,B!A1:E10000)} -> #VALUE! | N15: {=_FV(M15,"arrayPreview")} -> #VALUE!
A16: 9227 | B16: BASE PIZZA DOUGHBOYS (12PZ) CONG | C16: 23/01/2025 | D16: 230125 | E16: PIZZA GELO | F16: 1 | G16: 116
A17: 2283 | B17: BASE PALASTYLE (8PZ) | C17: 24/01/2025 | D17: 240125 | E17: PIZZA ATM | F17: 1 | G17: 27.5
A18: 9227 | B18: BASE PIZZA DOUGHBOYS (12PZ) CONG | C18: 24/01/2025 | D18: 240125 | E18: PIZZA GELO | F18: 1 | G18: 63.5
A19: 2543 | B19: PINSA ROMANA OVALE ATM | C19: 24/01/2025 | D19: 240125 | E19: PIZZA ATM | F19: 1 | G19: 34
A20: 9053 | B20: BASE PIZZA LINGUA ROMANA 55X19 GELO | C20: 27/01/2025 | D20: 270125 | E20: PIZZA GELO LB | F20: 1 | G20: 33
A21: 9227 | B21: BASE PIZZA DOUGHBOYS (12PZ) CONG | C21: 27/01/2025 | D21: 270125 | E21: PIZZA GELO | F21: 1 | G21: 30
A22: 9188 | B22: Base 20*40 400 g gelo pretagliata | C22: 28/01/2025 | D22: 280125 | E22: PIZZA GELO | F22: 1 | G22: 36
A23: 9227 | B23: BASE PIZZA DOUGHBOYS (12PZ) CONG | C23: 28/01/2025 | D23: 280125 | E23: PIZZA GELO | F23: 1 | G23: 63
A24: 2289 | B24: BASE PIZZA TONDA CLASSICA | C24: 29/01/2025 | D24: 290125 | E24: PIZZA ATM | F24: 1 | G24: 31
A25: 2283 | B25: BASE PALASTYLE (8PZ) | C25: 29/01/2025 | D25: 290125 | E25: PIZZA ATM | F25: 1 | G25: 36
A26: 9188 | B26: Base 20*40 400 g gelo pretagliata | C26: 29/01/2025 | D26: 290125 | E26: PIZZA GELO | F26: 1 | G26: 32
A27: 9201 | B27: PIZZICOTTA PINSA ROMANA 240 G | C27: 30/01/2025 | D27: 300125 | E27: PIZZA GELO | F27: 1 | G27: 21
A28: 2289 | B28: BASE PIZZA TONDA CLASSICA | C28: 30/01/2025 | D28: 300125 | E28: PIZZA ATM | F28: 1 | G28: 18 | M28: {=_xlfn._xlws.PY(10,1,L9,B!A1:E10000)} -> #VALUE! | N28: {=_FV(M28,"arrayPreview")} -> #VALUE!
A29: 2283 | B29: BASE PALASTYLE (8PZ) | C29: 30/01/2025 | D29: 300125 | E29: PIZZA ATM | F29: 1 | G29: 19.5
A30: 2290 | B30: BASE PIZZA INTEGRALE RETT MINI | C30: 30/01/2025 | D30: 300125 | E30: PIZZA ATM | F30: 1 | G30: 19.5
A31: 9188 | B31: Base 20*40 400 g gelo pretagliata | C31: 30/01/2025 | D31: 300125 | E31: PIZZA GELO | F31: 1 | G31: 26.5
A32: 9213 | B32: PAN PIZZA | C32: 31/01/2025 | D32: 310125 | E32: PIZZA GELO | F32: 1 | G32: 27
A33: 9053 | B33: BASE PIZZA LINGUA ROMANA 55X19 GELO | C33: 31/01/2025 | D33: 310125 | E33: PIZZA GELO LB | F33: 1 | G33: 22
A34: 9213 | B34: PAN PIZZA | C34: 03/02/2025 | D34: 030225 | E34: PIZZA GELO | F34: 1 | G34: 30
A35: 2553 | B35: Focaccina diam 10 cm 75 g | C35: 03/02/2025 | D35: 030225 | E35: PIZZA ATM | F35: 1 | G35: 14
A36: 9213 | B36: PAN PIZZA | C36: 04/02/2025 | D36: 040225 | E36: PIZZA GELO | F36: 1 | G36: 27
A37: 9053 | B37: BASE PIZZA LINGUA ROMANA 55X19 GELO | C37: 04/02/2025 | D37: 040225 | E37: PIZZA GELO LB | F37: 1 | G37: 40
A38: 9188 | B38: Base 20*40 400 g gelo pretagliata | C38: 04/02/2025 | D38: 040225 | E38: PIZZA GELO | F38: 1 | G38: 30
A39: 2543 | B39: PINSA ROMANA OVALE ATM | C39: 04/02/2025 | D39: 040225 | E39: PIZZA ATM | F39: 1 | G39: 23
A40: 9053 | B40: BASE PIZZA LINGUA ROMANA 55X19 GELO | C40: 05/02/2025 | D40: 050225 | E40: PIZZA GELO LB | F40: 1 | G40: 49
...

Sheet Foglio2
E1: civ in eur/lotto ccst
A2: 2738 | B2: 4320 | C2: 13 | D2: 104 | E2: 3532.65
A3: 9053 | B3: 2100 | C3: 11 | D3: 88 | E3: 3571.59
A4: 2283 | B4: 4200 | C4: 13 | D4: 104 | E4: 2111.61
A5: 2289 | B5: 2250 | C5: 7 | D5: 56
A6: 9187 | B6: 2500 | C6: 11 | D6: 88
A7: 9188 | B7: 2500 | C7: 11 | D7: 88 | E7: 2712.24
A8: 2736 | B8: 5500 | C8: 13 | D8: 104
A9: 9227 | B9: 5000 | C9: 13 | D9: 104
